Traceback (most recent call last):
  File "/opt/hostedtoolcache/Python/3.11.5/x64/lib/python3.11/site-packages/jupyter_cache/executors/utils.py", line 58, in single_nb_execution
    executenb(
  File "/opt/hostedtoolcache/Python/3.11.5/x64/lib/python3.11/site-packages/nbclient/client.py", line 1305, in execute
    return NotebookClient(nb=nb, resources=resources, km=km, **kwargs).execute()
           ^^^^^^^^^^^^^^^^^^^^^^^^^^^^^^^^^^^^^^^^^^^^^^^^^^^^^^^^^^^^^^^^^^^^^
  File "/opt/hostedtoolcache/Python/3.11.5/x64/lib/python3.11/site-packages/jupyter_core/utils/__init__.py", line 173, in wrapped
    return loop.run_until_complete(inner)
           ^^^^^^^^^^^^^^^^^^^^^^^^^^^^^^
  File "/opt/hostedtoolcache/Python/3.11.5/x64/lib/python3.11/asyncio/base_events.py", line 653, in run_until_complete
    return future.result()
           ^^^^^^^^^^^^^^^
  File "/opt/hostedtoolcache/Python/3.11.5/x64/lib/python3.11/site-packages/nbclient/client.py", line 705, in async_execute
    await self.async_execute_cell(
  File "/opt/hostedtoolcache/Python/3.11.5/x64/lib/python3.11/site-packages/nbclient/client.py", line 1058, in async_execute_cell
    await self._check_raise_for_error(cell, cell_index, exec_reply)
  File "/opt/hostedtoolcache/Python/3.11.5/x64/lib/python3.11/site-packages/nbclient/client.py", line 914, in _check_raise_for_error
    raise CellExecutionError.from_cell_and_msg(cell, exec_reply_content)
nbclient.exceptions.CellExecutionError: An error occurred while executing the following cell:
------------------
from keras.src.layers import SimpleRNN, Dense
from keras import Sequential

input_dim = 10  # change this to the number of input features in your dataset

model = Sequential()
model.add(SimpleRNN(50, activation='relu', input_shape=(None, input_dim)))
model.add(Dense(1))
model.compile(optimizer='adam', loss='mean_squared_error')
model.fit(x_train, y_train, epochs=100, verbose=0)
------------------


[0;31m---------------------------------------------------------------------------[0m
[0;31mValueError[0m                                Traceback (most recent call last)
Cell [0;32mIn[2], line 10[0m
[1;32m      8[0m model[38;5;241m.[39madd(Dense([38;5;241m1[39m))
[1;32m      9[0m model[38;5;241m.[39mcompile(optimizer[38;5;241m=[39m[38;5;124m'[39m[38;5;124madam[39m[38;5;124m'[39m, loss[38;5;241m=[39m[38;5;124m'[39m[38;5;124mmean_squared_error[39m[38;5;124m'[39m)
[0;32m---> 10[0m [43mmodel[49m[38;5;241;43m.[39;49m[43mfit[49m[43m([49m[43mx_train[49m[43m,[49m[43m [49m[43my_train[49m[43m,[49m[43m [49m[43mepochs[49m[38;5;241;43m=[39;49m[38;5;241;43m100[39;49m[43m,[49m[43m [49m[43mverbose[49m[38;5;241;43m=[39;49m[38;5;241;43m0[39;49m[43m)[49m

File [0;32m/opt/hostedtoolcache/Python/3.11.5/x64/lib/python3.11/site-packages/keras/src/utils/traceback_utils.py:70[0m, in [0;36mfilter_traceback.<locals>.error_handler[0;34m(*args, **kwargs)[0m
[1;32m     67[0m     filtered_tb [38;5;241m=[39m _process_traceback_frames(e[38;5;241m.[39m__traceback__)
[1;32m     68[0m     [38;5;66;03m# To get the full stack trace, call:[39;00m
[1;32m     69[0m     [38;5;66;03m# `tf.debugging.disable_traceback_filtering()`[39;00m
[0;32m---> 70[0m     [38;5;28;01mraise[39;00m e[38;5;241m.[39mwith_traceback(filtered_tb) [38;5;28;01mfrom[39;00m [38;5;28;01mNone[39;00m
[1;32m     71[0m [38;5;28;01mfinally[39;00m:
[1;32m     72[0m     [38;5;28;01mdel[39;00m filtered_tb

File [0;32m/opt/hostedtoolcache/Python/3.11.5/x64/lib/python3.11/site-packages/tensorflow/python/framework/constant_op.py:103[0m, in [0;36mconvert_to_eager_tensor[0;34m(value, ctx, dtype)[0m
[1;32m    101[0m     dtype [38;5;241m=[39m dtypes[38;5;241m.[39mas_dtype(dtype)[38;5;241m.[39mas_datatype_enum
[1;32m    102[0m ctx[38;5;241m.[39mensure_initialized()
[0;32m--> 103[0m [38;5;28;01mreturn[39;00m [43mops[49m[38;5;241;43m.[39;49m[43mEagerTensor[49m[43m([49m[43mvalue[49m[43m,[49m[43m [49m[43mctx[49m[38;5;241;43m.[39;49m[43mdevice_name[49m[43m,[49m[43m [49m[43mdtype[49m[43m)[49m

[0;31mValueError[0m: Failed to convert a NumPy array to a Tensor (Unsupported object type list).

