Traceback (most recent call last):
  File "C:\Users\legen\AppData\Roaming\Python\Python311\site-packages\jupyter_cache\executors\utils.py", line 58, in single_nb_execution
    executenb(
  File "C:\ProgramData\anaconda3\Lib\site-packages\nbclient\client.py", line 1204, in execute
    return NotebookClient(nb=nb, resources=resources, km=km, **kwargs).execute()
           ^^^^^^^^^^^^^^^^^^^^^^^^^^^^^^^^^^^^^^^^^^^^^^^^^^^^^^^^^^^^^^^^^^^^^
  File "C:\ProgramData\anaconda3\Lib\site-packages\nbclient\util.py", line 84, in wrapped
    return just_run(coro(*args, **kwargs))
           ^^^^^^^^^^^^^^^^^^^^^^^^^^^^^^^
  File "C:\ProgramData\anaconda3\Lib\site-packages\nbclient\util.py", line 62, in just_run
    return loop.run_until_complete(coro)
           ^^^^^^^^^^^^^^^^^^^^^^^^^^^^^
  File "C:\ProgramData\anaconda3\Lib\asyncio\base_events.py", line 653, in run_until_complete
    return future.result()
           ^^^^^^^^^^^^^^^
  File "C:\ProgramData\anaconda3\Lib\site-packages\nbclient\client.py", line 663, in async_execute
    await self.async_execute_cell(
  File "C:\ProgramData\anaconda3\Lib\site-packages\nbclient\client.py", line 965, in async_execute_cell
    await self._check_raise_for_error(cell, cell_index, exec_reply)
  File "C:\ProgramData\anaconda3\Lib\site-packages\nbclient\client.py", line 862, in _check_raise_for_error
    raise CellExecutionError.from_cell_and_msg(cell, exec_reply_content)
nbclient.exceptions.CellExecutionError: An error occurred while executing the following cell:
------------------
from keras.src.layers import SimpleRNN, Dense
from keras import Sequential

input_dim = 10  # change this to the number of input features in your dataset

model = Sequential()
model.add(SimpleRNN(50, activation='relu', input_shape=(None, input_dim)))
model.add(Dense(1))
model.compile(optimizer='adam', loss='mean_squared_error')
model.fit(x_train, y_train, epochs=100, verbose=0)
------------------

[1;31m---------------------------------------------------------------------------[0m
[1;31mValueError[0m                                Traceback (most recent call last)
Cell [1;32mIn[2], line 10[0m
[0;32m      8[0m model[38;5;241m.[39madd(Dense([38;5;241m1[39m))
[0;32m      9[0m model[38;5;241m.[39mcompile(optimizer[38;5;241m=[39m[38;5;124m'[39m[38;5;124madam[39m[38;5;124m'[39m, loss[38;5;241m=[39m[38;5;124m'[39m[38;5;124mmean_squared_error[39m[38;5;124m'[39m)
[1;32m---> 10[0m model[38;5;241m.[39mfit(x_train, y_train, epochs[38;5;241m=[39m[38;5;241m100[39m, verbose[38;5;241m=[39m[38;5;241m0[39m)

File [1;32m~\AppData\Roaming\Python\Python311\site-packages\keras\src\utils\traceback_utils.py:70[0m, in [0;36mfilter_traceback.<locals>.error_handler[1;34m(*args, **kwargs)[0m
[0;32m     67[0m     filtered_tb [38;5;241m=[39m _process_traceback_frames(e[38;5;241m.[39m__traceback__)
[0;32m     68[0m     [38;5;66;03m# To get the full stack trace, call:[39;00m
[0;32m     69[0m     [38;5;66;03m# `tf.debugging.disable_traceback_filtering()`[39;00m
[1;32m---> 70[0m     [38;5;28;01mraise[39;00m e[38;5;241m.[39mwith_traceback(filtered_tb) [38;5;28;01mfrom[39;00m [38;5;28;01mNone[39;00m
[0;32m     71[0m [38;5;28;01mfinally[39;00m:
[0;32m     72[0m     [38;5;28;01mdel[39;00m filtered_tb

File [1;32m~\AppData\Roaming\Python\Python311\site-packages\tensorflow\python\framework\constant_op.py:102[0m, in [0;36mconvert_to_eager_tensor[1;34m(value, ctx, dtype)[0m
[0;32m    100[0m     dtype [38;5;241m=[39m dtypes[38;5;241m.[39mas_dtype(dtype)[38;5;241m.[39mas_datatype_enum
[0;32m    101[0m ctx[38;5;241m.[39mensure_initialized()
[1;32m--> 102[0m [38;5;28;01mreturn[39;00m ops[38;5;241m.[39mEagerTensor(value, ctx[38;5;241m.[39mdevice_name, dtype)

[1;31mValueError[0m: Failed to convert a NumPy array to a Tensor (Unsupported object type list).
ValueError: Failed to convert a NumPy array to a Tensor (Unsupported object type list).

